Workbook

Sheet 當日比賽統計
B2: 勝敗 | C2: 主客 | D2: 隊名 | E2: 1 | F2: 2 | G2: 3 | H2: 4 | I2: 5 | J2: 6 | K2: 7 | L2: 8 | M2: R | N2: H | O2: E | P2: LOB | R2: 日期 | S2: 46013 | U2: 場地 | V2: 台大棒球場
B3: 勝 | C3: 主 | D3: 喝FIN就好BA | E3: 0 | F3: 0 | G3: 4 | H3: 0 | I3: 0 | J3: 0 | K3: 4 | M3: =countif('打 擊'!A:A,"R") -> 8 | N3: =sum(G6:G20) -> 11 | O3: =countif('投球守備'!P:P,"失誤") -> 2 | P3: =countif('打 擊'!A:A,"L") -> 7 | R3: 時間 | S3: 8：30 | U3: 天氣 | V3: 暖
B4: 敗 | C4: 客 | D4: 工海物治 | E4: 1 | F4: 0 | G4: 0 | H4: 0 | I4: 1 | J4: 5 | K4: 0 | M4: =countif('投球守備'!A:A,"R")+countif('投球守備'!A:A,"ER") -> 7 | N4: =sum(M25:M31)+sum(N25:N31) -> 10 | O4: =countif('打 擊'!P:P,"失誤") -> 1 | P4: =countif('投球守備'!A:A,"L") -> 6 | R4: 人數 | S4: 18 | U4: 紀錄 | V4: 徐瀅涵
B6: ORDER | E6: 打擊紀錄
B7: 棒次 | C7: 守位 | D7: 球員 | E7: 打席 | F7: 打數 | G7: 安打 | H7: 一安 | I7: 二安 | J7: 三安 | K7: 全壘打 | L7: 犧牲 | M7: 保送 | N7: 三振 | O7: 盜壘 | P7: 得分 | Q7: 打點 | S7: 大一 | T7: 大二 | U7: 大三 | V7: 大四 | W7: 王牌
B8: 1 | C8: SS | D8: 嚴敬翔 | E8: =countif('打 擊'!C:C,D8) -> 4 | F8: =E8-M8-L8 -> 4 | G8: =H8+I8+J8+K8 -> 2 | H8: =countifs('打 擊'!$C:$C,D8,'打 擊'!$P:$P,H$7) -> 2 | I8: =countifs('打 擊'!$C:$C,D8,'打 擊'!$P:$P,I$7) -> 0 | J8: =countifs('打 擊'!$C:$C,D8,'打 擊'!$P:$P,J$7) -> 0 | K8: =countifs('打 擊'!$C:$C,D8,'打 擊'!$P:$P,K$7) -> 0 | L8: =countifs('打 擊'!$C:$C,D8,'打 擊'!$P:$P,L$7) -> 0 | M8: =countifs('打 擊'!$C:$C,D8,'打 擊'!$P:$P,"觸身")+countifs('打 擊'!$C:$C,D8,'打 擊'!$P:$P,"保送") -> 0 | N8: =countifs('打 擊'!$C:$C,D8,'打 擊'!$P:$P,N$7) -> 0 | O8: =sumifs('打 擊'!$T:$T,'打 擊'!$C:$C,D8) -> 0 | P8: =countifs('打 擊'!$C:$C,D8,'打 擊'!$A:$A,"R") -> 1 | Q8: =sumifs('打 擊'!$X:$X,'打 擊'!$C:$C,D8) -> 0 | S8: 林育丞 | T8: 柯福恩 | U8: 方翰儒 | V8: 許振謙 | W8: 黃紹庭
B9: 2 | C9: 2B | D9: 蔡奇霖 | E9: =countif('打 擊'!C:C,D9) -> 4 | F9: =E9-M9-L9 -> 4 | G9: =H9+I9+J9+K9 -> 2 | H9: =countifs('打 擊'!$C:$C,D9,'打 擊'!$P:$P,H$7) -> 2 | I9: =countifs('打 擊'!$C:$C,D9,'打 擊'!$P:$P,I$7) -> 0 | J9: =countifs('打 擊'!$C:$C,D9,'打 擊'!$P:$P,J$7) -> 0 | K9: =countifs('打 擊'!$C:$C,D9,'打 擊'!$P:$P,K$7) -> 0 | L9: =countifs('打 擊'!$C:$C,D9,'打 擊'!$P:$P,L$7) -> 0 | M9: =countifs('打 擊'!$C:$C,D9,'打 擊'!$P:$P,"觸身")+countifs('打 擊'!$C:$C,D9,'打 擊'!$P:$P,"保送") -> 0 | N9: =countifs('打 擊'!$C:$C,D9,'打 擊'!$P:$P,N$7) -> 1 | O9: =sumifs('打 擊'!$T:$T,'打 擊'!$C:$C,D9) -> 0 | P9: =countifs('打 擊'!$C:$C,D9,'打 擊'!$A:$A,"R") -> 1 | Q9: =sumifs('打 擊'!$X:$X,'打 擊'!$C:$C,D9) -> 0 | S9: 卓育玄 | T9: 李原丞 | U9: 廖冠傑
B10: 3 | C10: C | D10: 梁睿至 | E10: =countif('打 擊'!C:C,D10) -> 4 | F10: =E10-M10-L10 -> 4 | G10: =H10+I10+J10+K10 -> 2 | H10: =countifs('打 擊'!$C:$C,D10,'打 擊'!$P:$P,H$7) -> 1 | I10: =countifs('打 擊'!$C:$C,D10,'打 擊'!$P:$P,I$7) -> 1 | J10: =countifs('打 擊'!$C:$C,D10,'打 擊'!$P:$P,J$7) -> 0 | K10: =countifs('打 擊'!$C:$C,D10,'打 擊'!$P:$P,K$7) -> 0 | L10: =countifs('打 擊'!$C:$C,D10,'打 擊'!$P:$P,L$7) -> 0 | M10: =countifs('打 擊'!$C:$C,D10,'打 擊'!$P:$P,"觸身")+countifs('打 擊'!$C:$C,D10,'打 擊'!$P:$P,"保送") -> 0 | N10: =countifs('打 擊'!$C:$C,D10,'打 擊'!$P:$P,N$7) -> 2 | O10: =sumifs('打 擊'!$T:$T,'打 擊'!$C:$C,D10) -> 0 | P10: =countifs('打 擊'!$C:$C,D10,'打 擊'!$A:$A,"R") -> 2 | Q10: =sumifs('打 擊'!$X:$X,'打 擊'!$C:$C,D10) -> 1 | S10: 杜秉鴻 | T10: 葉柏佑 | U10: 鄭守喆
B11: 4 | C11: 1B | D11: 許振謙 | E11: =countif('打 擊'!C:C,D11) -> 4 | F11: =E11-M11-L11 -> 3 | G11: =H11+I11+J11+K11 -> 1 | H11: =countifs('打 擊'!$C:$C,D11,'打 擊'!$P:$P,H$7) -> 1 | I11: =countifs('打 擊'!$C:$C,D11,'打 擊'!$P:$P,I$7) -> 0 | J11: =countifs('打 擊'!$C:$C,D11,'打 擊'!$P:$P,J$7) -> 0 | K11: =countifs('打 擊'!$C:$C,D11,'打 擊'!$P:$P,K$7) -> 0 | L11: =countifs('打 擊'!$C:$C,D11,'打 擊'!$P:$P,L$7) -> 0 | M11: =countifs('打 擊'!$C:$C,D11,'打 擊'!$P:$P,"觸身")+countifs('打 擊'!$C:$C,D11,'打 擊'!$P:$P,"保送") -> 1 | N11: =countifs('打 擊'!$C:$C,D11,'打 擊'!$P:$P,N$7) -> 0 | O11: =sumifs('打 擊'!$T:$T,'打 擊'!$C:$C,D11) -> 0 | P11: 0 | Q11: =sumifs('打 擊'!$X:$X,'打 擊'!$C:$C,D11) -> 2 | S11: 蔡侑廷 | T11: 張念詠 | U11: 陳柏承
C12: (PR) | D12: 蘇柏愷 | E12: =countif('打 擊'!C:C,D12) -> 0 | F12: =E12-M12-L12 -> 0 | G12: =H12+I12+J12+K12 -> 0 | H12: =countifs('打 擊'!$C:$C,D12,'打 擊'!$P:$P,H$7) -> 0 | I12: =countifs('打 擊'!$C:$C,D12,'打 擊'!$P:$P,I$7) -> 0 | J12: =countifs('打 擊'!$C:$C,D12,'打 擊'!$P:$P,J$7) -> 0 | K12: =countifs('打 擊'!$C:$C,D12,'打 擊'!$P:$P,K$7) -> 0 | L12: =countifs('打 擊'!$C:$C,D12,'打 擊'!$P:$P,L$7) -> 0 | M12: =countifs('打 擊'!$C:$C,D12,'打 擊'!$P:$P,"觸身")+countifs('打 擊'!$C:$C,D12,'打 擊'!$P:$P,"保送") -> 0 | N12: =countifs('打 擊'!$C:$C,D12,'打 擊'!$P:$P,N$7) -> 0 | O12: =sumifs('打 擊'!$T:$T,'打 擊'!$C:$C,D12) -> 0 | P12: 1 | Q12: =sumifs('打 擊'!$X:$X,'打 擊'!$C:$C,D12) -> 0 | S12: 陳冠瑋 | T12: 劉哲宏
B13: 5 | C13: CF(P) | D13: 劉哲宏 | E13: =countif('打 擊'!C:C,D13) -> 4 | F13: =E13-M13-L13 -> 4 | G13: =H13+I13+J13+K13 -> 1 | H13: =countifs('打 擊'!$C:$C,D13,'打 擊'!$P:$P,H$7) -> 1 | I13: =countifs('打 擊'!$C:$C,D13,'打 擊'!$P:$P,I$7) -> 0 | J13: =countifs('打 擊'!$C:$C,D13,'打 擊'!$P:$P,J$7) -> 0 | K13: =countifs('打 擊'!$C:$C,D13,'打 擊'!$P:$P,K$7) -> 0 | L13: =countifs('打 擊'!$C:$C,D13,'打 擊'!$P:$P,L$7) -> 0 | M13: =countifs('打 擊'!$C:$C,D13,'打 擊'!$P:$P,"觸身")+countifs('打 擊'!$C:$C,D13,'打 擊'!$P:$P,"保送") -> 0 | N13: =countifs('打 擊'!$C:$C,D13,'打 擊'!$P:$P,N$7) -> 2 | O13: =sumifs('打 擊'!$T:$T,'打 擊'!$C:$C,D13) -> 0 | P13: =countifs('打 擊'!$C:$C,D13,'打 擊'!$A:$A,"R") -> 0 | Q13: =sumifs('打 擊'!$X:$X,'打 擊'!$C:$C,D13) -> 0 | S13: 曾鉑棟 | T13: 陳威瑀
B14: 6 | C14: RF(CF) | D14: 劉品辰 | E14: =countif('打 擊'!C:C,D14) -> 4 | F14: =E14-M14-L14 -> 4 | G14: =H14+I14+J14+K14 -> 1 | H14: =countifs('打 擊'!$C:$C,D14,'打 擊'!$P:$P,H$7) -> 0 | I14: =countifs('打 擊'!$C:$C,D14,'打 擊'!$P:$P,I$7) -> 1 | J14: =countifs('打 擊'!$C:$C,D14,'打 擊'!$P:$P,J$7) -> 0 | K14: =countifs('打 擊'!$C:$C,D14,'打 擊'!$P:$P,K$7) -> 0 | L14: =countifs('打 擊'!$C:$C,D14,'打 擊'!$P:$P,L$7) -> 0 | M14: =countifs('打 擊'!$C:$C,D14,'打 擊'!$P:$P,"觸身")+countifs('打 擊'!$C:$C,D14,'打 擊'!$P:$P,"保送") -> 0 | N14: =countifs('打 擊'!$C:$C,D14,'打 擊'!$P:$P,N$7) -> 1 | O14: =sumifs('打 擊'!$T:$T,'打 擊'!$C:$C,D14) -> 0 | P14: =countifs('打 擊'!$C:$C,D14,'打 擊'!$A:$A,"R") -> 1 | Q14: =sumifs('打 擊'!$X:$X,'打 擊'!$C:$C,D14) -> 1 | S14: 吳冠廷 | T14: 邱孟賢
B15: 7 | C15: LF(3B) | D15: 王廷宇 | E15: =countif('打 擊'!C:C,D15) -> 4 | F15: =E15-M15-L15 -> 3 | G15: =H15+I15+J15+K15 -> 0 | H15: =countifs('打 擊'!$C:$C,D15,'打 擊'!$P:$P,H$7) -> 0 | I15: =countifs('打 擊'!$C:$C,D15,'打 擊'!$P:$P,I$7) -> 0 | J15: =countifs('打 擊'!$C:$C,D15,'打 擊'!$P:$P,J$7) -> 0 | K15: =countifs('打 擊'!$C:$C,D15,'打 擊'!$P:$P,K$7) -> 0 | L15: =countifs('打 擊'!$C:$C,D15,'打 擊'!$P:$P,L$7) -> 0 | M15: =countifs('打 擊'!$C:$C,D15,'打 擊'!$P:$P,"觸身")+countifs('打 擊'!$C:$C,D15,'打 擊'!$P:$P,"保送") -> 1 | N15: =countifs('打 擊'!$C:$C,D15,'打 擊'!$P:$P,N$7) -> 2 | O15: =sumifs('打 擊'!$T:$T,'打 擊'!$C:$C,D15) -> 1 | P15: =countifs('打 擊'!$C:$C,D15,'打 擊'!$A:$A,"R") -> 1 | Q15: =sumifs('打 擊'!$X:$X,'打 擊'!$C:$C,D15) -> 0
B16: 8 | C16: 3B(RF) | D16: 吳藹倫 | E16: =countif('打 擊'!C:C,D16) -> 4 | F16: =E16-M16-L16 -> 3 | G16: =H16+I16+J16+K16 -> 1 | H16: =countifs('打 擊'!$C:$C,D16,'打 擊'!$P:$P,H$7) -> 1 | I16: =countifs('打 擊'!$C:$C,D16,'打 擊'!$P:$P,I$7) -> 0 | J16: =countifs('打 擊'!$C:$C,D16,'打 擊'!$P:$P,J$7) -> 0 | K16: =countifs('打 擊'!$C:$C,D16,'打 擊'!$P:$P,K$7) -> 0 | L16: =countifs('打 擊'!$C:$C,D16,'打 擊'!$P:$P,L$7) -> 0 | M16: =countifs('打 擊'!$C:$C,D16,'打 擊'!$P:$P,"觸身")+countifs('打 擊'!$C:$C,D16,'打 擊'!$P:$P,"保送") -> 1 | N16: =countifs('打 擊'!$C:$C,D16,'打 擊'!$P:$P,N$7) -> 1 | O16: =sumifs('打 擊'!$T:$T,'打 擊'!$C:$C,D16) -> 1 | P16: =countifs('打 擊'!$C:$C,D16,'打 擊'!$A:$A,"R") -> 1 | Q16: =sumifs('打 擊'!$X:$X,'打 擊'!$C:$C,D16) -> 1
B17: 9 | C17: DH | D17: 黃襄璟 | E17: =countif('打 擊'!C:C,D17) -> 1 | F17: =E17-M17-L17 -> 1 | G17: =H17+I17+J17+K17 -> 0 | H17: =countifs('打 擊'!$C:$C,D17,'打 擊'!$P:$P,H$7) -> 0 | I17: =countifs('打 擊'!$C:$C,D17,'打 擊'!$P:$P,I$7) -> 0 | J17: =countifs('打 擊'!$C:$C,D17,'打 擊'!$P:$P,J$7) -> 0 | K17: =countifs('打 擊'!$C:$C,D17,'打 擊'!$P:$P,K$7) -> 0 | L17: =countifs('打 擊'!$C:$C,D17,'打 擊'!$P:$P,L$7) -> 0 | M17: =countifs('打 擊'!$C:$C,D17,'打 擊'!$P:$P,"觸身")+countifs('打 擊'!$C:$C,D17,'打 擊'!$P:$P,"保送") -> 0 | N17: =countifs('打 擊'!$C:$C,D17,'打 擊'!$P:$P,N$7) -> 1 | O17: =sumifs('打 擊'!$T:$T,'打 擊'!$C:$C,D17) -> 0 | P17: =countifs('打 擊'!$C:$C,D17,'打 擊'!$A:$A,"R") -> 0 | Q17: =sumifs('打 擊'!$X:$X,'打 擊'!$C:$C,D17) -> 0
C18: (PH)DH(CF)(LF) | D18: 鄭羣燁 | E18: =countif('打 擊'!C:C,D18) -> 3 | F18: =E18-M18-L18 -> 3 | G18: =H18+I18+J18+K18 -> 1 | H18: =countifs('打 擊'!$C:$C,D18,'打 擊'!$P:$P,H$7) -> 0 | I18: =countifs('打 擊'!$C:$C,D18,'打 擊'!$P:$P,I$7) -> 0 | J18: =countifs('打 擊'!$C:$C,D18,'打 擊'!$P:$P,J$7) -> 1 | K18: =countifs('打 擊'!$C:$C,D18,'打 擊'!$P:$P,K$7) -> 0 | L18: =countifs('打 擊'!$C:$C,D18,'打 擊'!$P:$P,L$7) -> 0 | M18: =countifs('打 擊'!$C:$C,D18,'打 擊'!$P:$P,"觸身")+countifs('打 擊'!$C:$C,D18,'打 擊'!$P:$P,"保送") -> 0 | N18: =countifs('打 擊'!$C:$C,D18,'打 擊'!$P:$P,N$7) -> 2 | O18: =sumifs('打 擊'!$T:$T,'打 擊'!$C:$C,D18) -> 0 | P18: =countifs('打 擊'!$C:$C,D18,'打 擊'!$A:$A,"R") -> 0 | Q18: =sumifs('打 擊'!$X:$X,'打 擊'!$C:$C,D18) -> 3
E19: =countif('打 擊'!C:C,D19) -> 0 | F19: =E19-M19-L19 -> 0 | G19: =H19+I19+J19+K19 -> 0 | H19: =countifs('打 擊'!$C:$C,D19,'打 擊'!$P:$P,H$7) -> 0 | I19: =countifs('打 擊'!$C:$C,D19,'打 擊'!$P:$P,I$7) -> 0 | J19: =countifs('打 擊'!$C:$C,D19,'打 擊'!$P:$P,J$7) -> 0 | K19: =countifs('打 擊'!$C:$C,D19,'打 擊'!$P:$P,K$7) -> 0 | L19: =countifs('打 擊'!$C:$C,D19,'打 擊'!$P:$P,L$7) -> 0 | M19: =countifs('打 擊'!$C:$C,D19,'打 擊'!$P:$P,"觸身")+countifs('打 擊'!$C:$C,D19,'打 擊'!$P:$P,"保送") -> 0 | N19: =countifs('打 擊'!$C:$C,D19,'打 擊'!$P:$P,N$7) -> 0 | O19: =sumifs('打 擊'!$T:$T,'打 擊'!$C:$C,D19) -> 0 | P19: =countifs('打 擊'!$C:$C,D19,'打 擊'!$A:$A,"R") -> 0 | Q19: =sumifs('打 擊'!$X:$X,'打 擊'!$C:$C,D19) -> 0
E20: =countif('打 擊'!C:C,D20) -> 0 | F20: =E20-M20-L20 -> 0 | G20: =H20+I20+J20+K20 -> 0 | H20: =countifs('打 擊'!$C:$C,D20,'打 擊'!$P:$P,H$7) -> 0 | I20: =countifs('打 擊'!$C:$C,D20,'打 擊'!$P:$P,I$7) -> 0 | J20: =countifs('打 擊'!$C:$C,D20,'打 擊'!$P:$P,J$7) -> 0 | K20: =countifs('打 擊'!$C:$C,D20,'打 擊'!$P:$P,K$7) -> 0 | L20: =countifs('打 擊'!$C:$C,D20,'打 擊'!$P:$P,L$7) -> 0 | M20: =countifs('打 擊'!$C:$C,D20,'打 擊'!$P:$P,"觸身")+countifs('打 擊'!$C:$C,D20,'打 擊'!$P:$P,"保送") -> 0 | N20: =countifs('打 擊'!$C:$C,D20,'打 擊'!$P:$P,N$7) -> 0 | O20: =sumifs('打 擊'!$T:$T,'打 擊'!$C:$C,D20) -> 0 | P20: =countifs('打 擊'!$C:$C,D20,'打 擊'!$A:$A,"R") -> 0 | Q20: =sumifs('打 擊'!$X:$X,'打 擊'!$C:$C,D20) -> 0 | R20: AVG | S20: OBP | T20: SLG | U20: OPS
D21: 總和 | E21: =sum(E8:E20) -> 36 | F21: =E21-M21-L21 -> 33 | G21: =H21+I21+J21+K21 -> 11 | H21: =sum(H8:H20) -> 8 | I21: =sum(I8:I20) -> 2 | J21: =sum(J8:J20) -> 1 | K21: =sum(K8:K20) -> 0 | L21: =sum(L8:L20) -> 0 | M21: =sum(M8:M20) -> 3 | N21: =sum(N8:N20) -> 12 | O21: =sum(O8:O20) -> 2 | ... Q21: =sum(Q8:Q20) -> 8 | R21: =iferror(G21/F21,0) -> 0.33333333 | S21: =iferror((G21+M21)/(E21-L21),0) -> 0.38888889 | T21: =iferror((H21+I21*2+J21*3+K21*4)/F21,0) -> 0.45454545 | U21: =S21+T21 -> 0.84343434
B23: ORDER | E23: 投球紀錄
B24: 勝敗 | C24: 任務 | D24: 球員 | E24: 局數 | F24: 人次 | G24: 用球數 | H24: 好球 | I24: 壞球 | J24: 三振 | K24: 保送 | L24: 觸身 | M24: 安打 | N24: 全壘打 | O24: 失分 | P24: 責失 | Q24: ERA | R24: WHIP | S24: S%
C25: SP | D25: 林昱丞 | E25: =(countifs('投球守備'!$C:$C,$D25,'投球守備'!$A:$A,"I")+countifs('投球守備'!$C:$C,$D25,'投球守備'!$A:$A,"II")+countifs('投球守備'!$C:$C,$D25,'投球守備'!$A:$A,"III"))/3 -> 4.6666667 | F25: =countif('投球守備'!C:C,D25) -> 19 | G25: =H25+I25 -> 72 | H25: =sumifs('投球守備'!$M:$M,'投球守備'!$C:$C,$D25)+sumifs('投球守備'!$N:$N,'投球守備'!$C:$C,$D25) -> 44 | I25: =sumifs('投球守備'!$O:$O,'投球守備'!$C:$C,$D25) -> 28 | J25: =countifs('投球守備'!$C:$C,$D25,'投球守備'!$P:$P,J$24) -> 4 | K25: =countifs('投球守備'!$C:$C,$D25,'投球守備'!$P:$P,K$24) -> 2 | L25: =countifs('投球守備'!$C:$C,$D25,'投球守備'!$P:$P,L$24) -> 0 | M25: =countifs('投球守備'!$C:$C,$D25,'投球守備'!$P:$P,"一安")+countifs('投球守備'!$C:$C,$D25,'投球守備'!$P:$P,"二安")+countifs('投球守備'!$C:$C,$D25,'投球守備'!$P:$P,"三安")+countifs('投球守備'!$C:$C,$D25,'投球守備'!$P:$P,"內安") -> 4 | N25: =countifs('投球守備'!$C:$C,$D25,'投球守備'!$P:$P,N$24) -> 0 | O25: =countifs('投球守備'!$C:$C,$D25,'投球守備'!A:A,"R")+countifs('投球守備'!$C:$C,$D25,'投球守備'!A:A,"ER") -> 2 | P25: =countifs('投球守備'!$C:$C,$D25,'投球守備'!A:A,"ER") -> 2 | Q25: =iferror(P25/E25*7,0) -> 3 | R25: =IFERROR((K25+L25+M25+N25)/E25,0) -> 1.2857143 | S25: =iferror(H25/G25,0) -> 0.61111111 | U25: 黃紹庭
C26: RP | D26: 曾亭維 | E26: 0.67 | F26: =countif('投球守備'!C:C,D26) -> 5 | G26: =H26+I26 -> 19 | H26: =sumifs('投球守備'!$M:$M,'投球守備'!$C:$C,$D26)+sumifs('投球守備'!$N:$N,'投球守備'!$C:$C,$D26) -> 8 | I26: =sumifs('投球守備'!$O:$O,'投球守備'!$C:$C,$D26) -> 11 | J26: =countifs('投球守備'!$C:$C,$D26,'投球守備'!$P:$P,J$24) -> 1 | K26: =countifs('投球守備'!$C:$C,$D26,'投球守備'!$P:$P,K$24) -> 1 | L26: =countifs('投球守備'!$C:$C,$D26,'投球守備'!$P:$P,L$24) -> 0 | M26: =countifs('投球守備'!$C:$C,$D26,'投球守備'!$P:$P,"一安")+countifs('投球守備'!$C:$C,$D26,'投球守備'!$P:$P,"二安")+countifs('投球守備'!$C:$C,$D26,'投球守備'!$P:$P,"三安")+countifs('投球守備'!$C:$C,$D26,'投球守備'!$P:$P,"內安") -> 1 | N26: =countifs('投球守備'!$C:$C,$D26,'投球守備'!$P:$P,N$24) -> 0 | O26: =countifs('投球守備'!$C:$C,$D26,'投球守備'!A:A,"R")+countifs('投球守備'!$C:$C,$D26,'投球守備'!A:A,"ER") -> 0 | P26: =countifs('投球守備'!$C:$C,$D26,'投球守備'!A:A,"ER") -> 0 | Q26: =iferror(P26/E26*7,0) -> 0 | R26: =IFERROR((K26+L26+M26+N26)/E26,0) -> 2.9850746 | S26: =iferror(H26/G26,0) -> 0.42105263 | U26: 鄭守喆
C27: RP | D27: 林凱堉 | E27: =0.33 -> 0.33 | F27: =countif('投球守備'!C:C,D27) -> 5 | G27: =H27+I27 -> 18 | H27: =sumifs('投球守備'!$M:$M,'投球守備'!$C:$C,$D27)+sumifs('投球守備'!$N:$N,'投球守備'!$C:$C,$D27) -> 10 | I27: =sumifs('投球守備'!$O:$O,'投球守備'!$C:$C,$D27) -> 8 | J27: =countifs('投球守備'!$C:$C,$D27,'投球守備'!$P:$P,J$24) -> 0 | K27: =countifs('投球守備'!$C:$C,$D27,'投球守備'!$P:$P,K$24) -> 1 | L27: =countifs('投球守備'!$C:$C,$D27,'投球守備'!$P:$P,L$24) -> 0 | M27: =countifs('投球守備'!$C:$C,$D27,'投球守備'!$P:$P,"一安")+countifs('投球守備'!$C:$C,$D27,'投球守備'!$P:$P,"二安")+countifs('投球守備'!$C:$C,$D27,'投球守備'!$P:$P,"三安")+countifs('投球守備'!$C:$C,$D27,'投球守備'!$P:$P,"內安") -> 3 | N27: =countifs('投球守備'!$C:$C,$D27,'投球守備'!$P:$P,N$24) -> 0 | O27: =countifs('投球守備'!$C:$C,$D27,'投球守備'!A:A,"R")+countifs('投球守備'!$C:$C,$D27,'投球守備'!A:A,"ER") -> 5 | P27: =countifs('投球守備'!$C:$C,$D27,'投球守備'!A:A,"ER") -> 0 | Q27: =iferror(P27/E27*7,0) -> 0 | R27: =IFERROR((K27+L27+M27+N27)/E27,0) -> 12.121212 | S27: =iferror(H27/G27,0) -> 0.55555556 | U27: 劉哲宏
C28: CP | D28: 劉哲宏 | E28: =(countifs('投球守備'!$C:$C,$D28,'投球守備'!$A:$A,"I")+countifs('投球守備'!$C:$C,$D28,'投球守備'!$A:$A,"II")+countifs('投球守備'!$C:$C,$D28,'投球守備'!$A:$A,"III"))/3 -> 1.3333333 | F28: =countif('投球守備'!C:C,D28) -> 5 | G28: =H28+I28 -> 17 | H28: =sumifs('投球守備'!$M:$M,'投球守備'!$C:$C,$D28)+sumifs('投球守備'!$N:$N,'投球守備'!$C:$C,$D28) -> 11 | I28: =sumifs('投球守備'!$O:$O,'投球守備'!$C:$C,$D28) -> 6 | J28: =countifs('投球守備'!$C:$C,$D28,'投球守備'!$P:$P,J$24) -> 0 | K28: =countifs('投球守備'!$C:$C,$D28,'投球守備'!$P:$P,K$24) -> 1 | L28: =countifs('投球守備'!$C:$C,$D28,'投球守備'!$P:$P,L$24) -> 0 | M28: =countifs('投球守備'!$C:$C,$D28,'投球守備'!$P:$P,"一安")+countifs('投球守備'!$C:$C,$D28,'投球守備'!$P:$P,"二安")+countifs('投球守備'!$C:$C,$D28,'投球守備'!$P:$P,"三安") -> 2 | N28: =countifs('投球守備'!$C:$C,$D28,'投球守備'!$P:$P,N$24) -> 0 | O28: =countifs('投球守備'!$C:$C,$D28,'投球守備'!A:A,"R")+countifs('投球守備'!$C:$C,$D28,'投球守備'!A:A,"ER") -> 0 | P28: =countifs('投球守備'!$C:$C,$D28,'投球守備'!A:A,"ER") -> 0 | Q28: =iferror(P28/E28*7,0) -> 0 | R28: =IFERROR((K28+L28+M28+N28)/E28,0) -> 2.25 | S28: =iferror(H28/G28,0) -> 0.64705882 | U28: 劉丞晏
E29: =(countifs('投球守備'!$C:$C,$D29,'投球守備'!$A:$A,"I")+countifs('投球守備'!$C:$C,$D29,'投球守備'!$A:$A,"II")+countifs('投球守備'!$C:$C,$D29,'投球守備'!$A:$A,"III"))/3 -> 0 | F29: =countif('投球守備'!C:C,D29) -> 0 | G29: =H29+I29 -> 0 | H29: =sumifs('投球守備'!$M:$M,'投球守備'!$C:$C,$D29)+sumifs('投球守備'!$N:$N,'投球守備'!$C:$C,$D29) -> 0 | I29: =sumifs('投球守備'!$O:$O,'投球守備'!$C:$C,$D29) -> 0 | J29: =countifs('投球守備'!$C:$C,$D29,'投球守備'!$P:$P,J$24) -> 0 | K29: =countifs('投球守備'!$C:$C,$D29,'投球守備'!$P:$P,K$24) -> 0 | L29: =countifs('投球守備'!$C:$C,$D29,'投球守備'!$P:$P,L$24) -> 0 | M29: =countifs('投球守備'!$C:$C,$D29,'投球守備'!$P:$P,"一安")+countifs('投球守備'!$C:$C,$D29,'投球守備'!$P:$P,"二安")+countifs('投球守備'!$C:$C,$D29,'投球守備'!$P:$P,"三安") -> 0 | N29: =countifs('投球守備'!$C:$C,$D29,'投球守備'!$P:$P,N$24) -> 0 | O29: =countifs('投球守備'!$C:$C,$D29,'投球守備'!A:A,"R")+countifs('投球守備'!$C:$C,$D29,'投球守備'!A:A,"ER") -> 0 | P29: =countifs('投球守備'!$C:$C,$D29,'投球守備'!A:A,"ER") -> 0 | Q29: =iferror(P29/E29*7,0) -> 0 | R29: =IFERROR((K29+L29+M29+N29)/E29,0) -> 0 | S29: =iferror(H29/G29,0) -> 0 | U29: 林育丞
E30: =(countifs('投球守備'!$C:$C,$D30,'投球守備'!$A:$A,"I")+countifs('投球守備'!$C:$C,$D30,'投球守備'!$A:$A,"II")+countifs('投球守備'!$C:$C,$D30,'投球守備'!$A:$A,"III"))/3 -> 0 | F30: =countif('投球守備'!C:C,D30) -> 0 | G30: =H30+I30 -> 0 | H30: =sumifs('投球守備'!$M:$M,'投球守備'!$C:$C,$D30)+sumifs('投球守備'!$N:$N,'投球守備'!$C:$C,$D30) -> 0 | I30: =sumifs('投球守備'!$O:$O,'投球守備'!$C:$C,$D30) -> 0 | J30: =countifs('投球守備'!$C:$C,$D30,'投球守備'!$P:$P,J$24) -> 0 | K30: =countifs('投球守備'!$C:$C,$D30,'投球守備'!$P:$P,K$24) -> 0 | L30: =countifs('投球守備'!$C:$C,$D30,'投球守備'!$P:$P,L$24) -> 0 | M30: =countifs('投球守備'!$C:$C,$D30,'投球守備'!$P:$P,"一安")+countifs('投球守備'!$C:$C,$D30,'投球守備'!$P:$P,"二安")+countifs('投球守備'!$C:$C,$D30,'投球守備'!$P:$P,"三安") -> 0 | N30: =countifs('投球守備'!$C:$C,$D30,'投球守備'!$P:$P,N$24) -> 0 | O30: =countifs('投球守備'!$C:$C,$D30,'投球守備'!A:A,"R")+countifs('投球守備'!$C:$C,$D30,'投球守備'!A:A,"ER") -> 0 | P30: =countifs('投球守備'!$C:$C,$D30,'投球守備'!A:A,"ER") -> 0 | Q30: =iferror(P30/E30*7,0) -> 0 | R30: =IFERROR((K30+L30+M30+N30)/E30,0) -> 0 | S30: =iferror(H30/G30,0) -> 0 | U30: 卓育玄
E31: =(countifs('投球守備'!$C:$C,$D31,'投球守備'!$A:$A,"I")+countifs('投球守備'!$C:$C,$D31,'投球守備'!$A:$A,"II")+countifs('投球守備'!$C:$C,$D31,'投球守備'!$A:$A,"III"))/3 -> 0 | F31: =countif('投球守備'!C:C,D31) -> 0 | G31: =H31+I31 -> 0 | H31: =sumifs('投球守備'!$M:$M,'投球守備'!$C:$C,$D31)+sumifs('投球守備'!$N:$N,'投球守備'!$C:$C,$D31) -> 0 | I31: =sumifs('投球守備'!$O:$O,'投球守備'!$C:$C,$D31) -> 0 | J31: =countifs('投球守備'!$C:$C,$D31,'投球守備'!$P:$P,J$24) -> 0 | K31: =countifs('投球守備'!$C:$C,$D31,'投球守備'!$P:$P,K$24) -> 0 | L31: =countifs('投球守備'!$C:$C,$D31,'投球守備'!$P:$P,L$24) -> 0 | M31: =countifs('投球守備'!$C:$C,$D31,'投球守備'!$P:$P,"一安")+countifs('投球守備'!$C:$C,$D31,'投球守備'!$P:$P,"二安")+countifs('投球守備'!$C:$C,$D31,'投球守備'!$P:$P,"三安") -> 0 | N31: =countifs('投球守備'!$C:$C,$D31,'投球守備'!$P:$P,N$24) -> 0 | O31: =countifs('投球守備'!$C:$C,$D31,'投球守備'!A:A,"R")+countifs('投球守備'!$C:$C,$D31,'投球守備'!A:A,"ER") -> 0 | P31: =countifs('投球守備'!$C:$C,$D31,'投球守備'!A:A,"ER") -> 0 | Q31: =iferror(P31/E31*7,0) -> 0 | R31: =IFERROR((K31+L31+M31+N31)/E31,0) -> 0 | S31: =iferror(H31/G31,0) -> 0
D32: 總和 | E32: =sum(E25:E31) -> 7 | F32: =sum(F25:F31) -> 34 | G32: =sum(G25:G31) -> 126 | H32: =sum(H25:H31) -> 73 | I32: =sum(I25:I31) -> 53 | J32: =sum(J25:J31) -> 5 | K32: =sum(K25:K31) -> 5 | L32: =sum(L25:L31) -> 0 | ... P32: =sum(P25:P31) -> 2 | Q32: =iferror(P32/E32*7,"0.00") -> 2 | R32: =IFERROR((K32+L32+M32+N32)/E32,"0.00") -> 2.1428571 | S32: =iferror(H32/G32,"0.00") -> 0.57936508

Sheet 打　擊
A1: 結果 | B1: 棒次 | C1: 打者姓名 | D1: 逐球 | M1: 好 | N1: 界外 | O1: 壞 | P1: 打擊結果 | Q1: 擊球軌跡 | S1: 內容 | T1: 盜壘 | U1: 失誤進壘 | V1: 壘死 | W1: 得分 | X1: 打點 | Y1: 備註
B2: 1 | C2: 范立 | D2: SS | E2: CS | F2: IP | G2: B | H2: F | M2: =countif(D2:L2,"=S")+countif(D2:L2,"=SS")+countif(D2:L2,"=CS")+countif(D2:L2,"=IP") -> 3 | N2: =countif(D2:L2,"=F") -> 1 | O2: =countif(D2:L2,"=B") -> 1 | P2: 一安 | Q2: 4 | R2: G | S2: 強 | T2: 1 | U2: 1 | V2: 0 | W2: 0 | X2: 1
A3: I | B3: 1 | C3: ='當日比賽統計'!D8 -> 嚴敬翔 | D3: B | E3: IP | M3: =countif(D3:L3,"=S")+countif(D3:L3,"=SS")+countif(D3:L3,"=CS")+countif(D3:L3,"=IP") -> 1 | N3: =countif(D3:L3,"=F") -> 0 | O3: =countif(D3:L3,"=B") -> 1 | P3: 內滾 | Q3: 5三壘
A4: L | B4: 2 | C4: ='當日比賽統計'!D9 -> 蔡奇霖 | D4: B | E4: IP | M4: =countif(D4:L4,"=S")+countif(D4:L4,"=SS")+countif(D4:L4,"=CS")+countif(D4:L4,"=IP") -> 1 | N4: =countif(D4:L4,"=F") -> 0 | O4: =countif(D4:L4,"=B") -> 1 | P4: 失誤 | Q4: 5三壘 | R4: G | S4: 中 | U4: 1
A5: II | B5: 3 | C5: ='當日比賽統計'!D10 -> 梁睿至 | D5: CS | E5: B | F5: F | G5: B | H5: SS | M5: =countif(D5:L5,"=S")+countif(D5:L5,"=SS")+countif(D5:L5,"=CS")+countif(D5:L5,"=IP") -> 2 | N5: =countif(D5:L5,"=F") -> 1 | O5: =countif(D5:L5,"=B") -> 2 | P5: 三振
A6: III | B6: 4 | C6: ='當日比賽統計'!D11 -> 許振謙 | D6: IP | M6: =countif(D6:L6,"=S")+countif(D6:L6,"=SS")+countif(D6:L6,"=CS")+countif(D6:L6,"=IP") -> 1 | N6: =countif(D6:L6,"=F") -> 0 | O6: =countif(D6:L6,"=B") -> 0 | P6: 外飛 | Q6: 9右外 | R6: F | S6: 中
A7: I | B7: 5 | C7: ='當日比賽統計'!D13 -> 劉哲宏 | D7: CS | E7: B | F7: CS | G7: F | H7: B | I7: SS | M7: =countif(D7:L7,"=S")+countif(D7:L7,"=SS")+countif(D7:L7,"=CS")+countif(D7:L7,"=IP") -> 3 | N7: =countif(D7:L7,"=F") -> 1 | O7: =countif(D7:L7,"=B") -> 2 | P7: 三振
A8: II | B8: 6 | C8: ='當日比賽統計'!D14 -> 劉品辰 | D8: B | E8: CS | F8: CS | G8: B | H8: SS | M8: =countif(D8:L8,"=S")+countif(D8:L8,"=SS")+countif(D8:L8,"=CS")+countif(D8:L8,"=IP") -> 3 | N8: =countif(D8:L8,"=F") -> 0 | O8: =countif(D8:L8,"=B") -> 2 | P8: 三振
A9: R | B9: 7 | C9: ='當日比賽統計'!D15 -> 王廷宇 | D9: B | E9: B | F9: F | G9: SS | H9: SS | M9: =countif(D9:L9,"=S")+countif(D9:L9,"=SS")+countif(D9:L9,"=CS")+countif(D9:L9,"=IP") -> 2 | N9: =countif(D9:L9,"=F") -> 1 | O9: =countif(D9:L9,"=B") -> 2 | P9: 三振 | T9: 1 | U9: 2 | W9: 1 | Y9: 不死三振
A10: L | B10: 8 | C10: ='當日比賽統計'!D16 -> 吳藹倫 | D10: SS | E10: B | F10: CS | G10: B | M10: =countif(D10:L10,"=S")+countif(D10:L10,"=SS")+countif(D10:L10,"=CS")+countif(D10:L10,"=IP") -> 2 | N10: =countif(D10:L10,"=F") -> 0 | O10: =countif(D10:L10,"=B") -> 2 | P10: 一安 | Q10: 9右外 | R10: G | S10: 中 | T10: 1 | X10: 1
A11: III | B11: 9 | C11: ='當日比賽統計'!D17 -> 黃襄璟 | D11: CS | E11: B | F11: F | G11: B | H11: SS | M11: =countif(D11:L11,"=S")+countif(D11:L11,"=SS")+countif(D11:L11,"=CS")+countif(D11:L11,"=IP") -> 2 | N11: =countif(D11:L11,"=F") -> 1 | O11: =countif(D11:L11,"=B") -> 2 | P11: 三振
A12: R | B12: 1 | C12: 嚴敬翔 | D12: CS | E12: IP | M12: =countif(D12:L12,"=S")+countif(D12:L12,"=SS")+countif(D12:L12,"=CS")+countif(D12:L12,"=IP") -> 2 | N12: =countif(D12:L12,"=F") -> 0 | O12: =countif(D12:L12,"=B") -> 0 | P12: 一安 | Q12: 7左外 | R12: G | S12: 強 | U12: 1 | W12: 1
A13: R | B13: 2 | C13: 蔡奇霖 | D13: CS | E13: IP | M13: =countif(D13:L13,"=S")+countif(D13:L13,"=SS")+countif(D13:L13,"=CS")+countif(D13:L13,"=IP") -> 2 | N13: =countif(D13:L13,"=F") -> 0 | O13: =countif(D13:L13,"=B") -> 0 | P13: 一安 | Q13: 9右外 | R13: G | S13: 強 | W13: 1
A14: R | B14: 3 | C14: 梁睿至 | D14: SS | E14: IP | M14: =countif(D14:L14,"=S")+countif(D14:L14,"=SS")+countif(D14:L14,"=CS")+countif(D14:L14,"=IP") -> 2 | N14: =countif(D14:L14,"=F") -> 0 | O14: =countif(D14:L14,"=B") -> 0 | P14: 二安 | Q14: 7左外 | R14: L | S14: 中 | W14: 1 | X14: 1
A15: L | B15: 4 | C15: 許振謙 | D15: SS | E15: IP | M15: =countif(D15:L15,"=S")+countif(D15:L15,"=SS")+countif(D15:L15,"=CS")+countif(D15:L15,"=IP") -> 2 | N15: =countif(D15:L15,"=F") -> 0 | O15: =countif(D15:L15,"=B") -> 0 | P15: 一安 | Q15: 9右外 | R15: G | S15: 強 | U15: 1 | X15: 2
A16: I | B16: 5 | C16: 劉哲宏 | D16: IP | M16: =countif(D16:L16,"=S")+countif(D16:L16,"=SS")+countif(D16:L16,"=CS")+countif(D16:L16,"=IP") -> 1 | N16: =countif(D16:L16,"=F") -> 0 | O16: =countif(D16:L16,"=B") -> 0 | P16: 內滾 | Q16: 1投手 | R16: G | S16: 中
A17: II | B17: 6 | C17: 劉品辰 | D17: B | E17: IP | M17: =countif(D17:L17,"=S")+countif(D17:L17,"=SS")+countif(D17:L17,"=CS")+countif(D17:L17,"=IP") -> 1 | N17: =countif(D17:L17,"=F") -> 0 | O17: =countif(D17:L17,"=B") -> 1 | P17: 內飛 | Q17: 3一壘 | R17: F | S17: 中
A18: L | B18: 7 | C18: 王廷宇 | D18: CS | E18: B | M18: =countif(D18:L18,"=S")+countif(D18:L18,"=SS")+countif(D18:L18,"=CS")+countif(D18:L18,"=IP") -> 1 | N18: =countif(D18:L18,"=F") -> 0 | O18: =countif(D18:L18,"=B") -> 1 | P18: 觸身
A19: III | B19: 8 | C19: 吳藹倫 | D19: CS | E19: B | M19: =countif(D19:L19,"=S")+countif(D19:L19,"=SS")+countif(D19:L19,"=CS")+countif(D19:L19,"=IP") -> 1 | N19: =countif(D19:L19,"=F") -> 0 | O19: =countif(D19:L19,"=B") -> 1 | P19: 內滾 | Q19: 3一壘 | R19: G | S19: 中
A20: I | B20: 9 | C20: 鄭羣燁 | D20: CS | E20: SS | F20: F | G20: B | H20: CS | M20: =countif(D20:L20,"=S")+countif(D20:L20,"=SS")+countif(D20:L20,"=CS")+countif(D20:L20,"=IP") -> 3 | N20: =countif(D20:L20,"=F") -> 1 | O20: =countif(D20:L20,"=B") -> 1 | P20: 三振
A21: L | B21: 1 | C21: 嚴敬翔 | D21: B | E21: B | F21: CS | G21: B | H21: CS | I21: IP | M21: =countif(D21:L21,"=S")+countif(D21:L21,"=SS")+countif(D21:L21,"=CS")+countif(D21:L21,"=IP") -> 3 | N21: =countif(D21:L21,"=F") -> 0 | O21: =countif(D21:L21,"=B") -> 3 | P21: 一安 | Q21: 9右外 | R21: G | S21: 強
A22: L | B22: 2 | C22: 蔡奇霖 | D22: SS | E22: CS | F22: IP | M22: =countif(D22:L22,"=S")+countif(D22:L22,"=SS")+countif(D22:L22,"=CS")+countif(D22:L22,"=IP") -> 3 | N22: =countif(D22:L22,"=F") -> 0 | O22: =countif(D22:L22,"=B") -> 0 | P22: 一安 | Q22: 7左外 | R22: G | S22: 強
A23: II | B23: 3 | C23: 梁睿至 | D23: F | E23: CS | F23: SS | M23: =countif(D23:L23,"=S")+countif(D23:L23,"=SS")+countif(D23:L23,"=CS")+countif(D23:L23,"=IP") -> 2 | N23: =countif(D23:L23,"=F") -> 1 | O23: =countif(D23:L23,"=B") -> 0 | P23: 三振
A24: III | B24: 4 | C24: 許振謙 | D24: IP | M24: =countif(D24:L24,"=S")+countif(D24:L24,"=SS")+countif(D24:L24,"=CS")+countif(D24:L24,"=IP") -> 1 | N24: =countif(D24:L24,"=F") -> 0 | O24: =countif(D24:L24,"=B") -> 0 | P24: 內滾 | Q24: 5三壘 | R24: G | S24: 弱
A25: L | B25: 5 | C25: 劉哲宏 | D25: B | E25: CS | F25: F | G25: B | H25: B | I25: F | J25: IP | M25: =countif(D25:L25,"=S")+countif(D25:L25,"=SS")+countif(D25:L25,"=CS")+countif(D25:L25,"=IP") -> 2 | N25: =countif(D25:L25,"=F") -> 2 | O25: =countif(D25:L25,"=B") -> 3 | P25: 一安 | Q25: 7左外 | R25: G | S25: 強
A26: I | B26: 6 | C26: 劉品辰 | D26: IP | M26: =countif(D26:L26,"=S")+countif(D26:L26,"=SS")+countif(D26:L26,"=CS")+countif(D26:L26,"=IP") -> 1 | N26: =countif(D26:L26,"=F") -> 0 | O26: =countif(D26:L26,"=B") -> 0 | P26: 外飛 | Q26: 7左外 | R26: F | S26: 中
A27: II | B27: 7 | C27: 王廷宇 | D27: SS | E27: SS | F27: CS | M27: =countif(D27:L27,"=S")+countif(D27:L27,"=SS")+countif(D27:L27,"=CS")+countif(D27:L27,"=IP") -> 3 | N27: =countif(D27:L27,"=F") -> 0 | O27: =countif(D27:L27,"=B") -> 0 | P27: 三振
A28: III | B28: 8 | C28: 吳藹倫 | D28: CS | E28: B | F28: CS | G28: CS | M28: =countif(D28:L28,"=S")+countif(D28:L28,"=SS")+countif(D28:L28,"=CS")+countif(D28:L28,"=IP") -> 3 | N28: =countif(D28:L28,"=F") -> 0 | O28: =countif(D28:L28,"=B") -> 1 | P28: 三振
A29: I | B29: 9 | C29: 鄭羣燁 | D29: SS | E29: B | F29: CS | G29: F | H29: SS | M29: =countif(D29:L29,"=S")+countif(D29:L29,"=SS")+countif(D29:L29,"=CS")+countif(D29:L29,"=IP") -> 3 | N29: =countif(D29:L29,"=F") -> 1 | O29: =countif(D29:L29,"=B") -> 1 | P29: 三振
A30: II | B30: 1 | C30: 嚴敬翔 | D30: F | E30: IP | M30: =countif(D30:L30,"=S")+countif(D30:L30,"=SS")+countif(D30:L30,"=CS")+countif(D30:L30,"=IP") -> 1 | N30: =countif(D30:L30,"=F") -> 1 | O30: =countif(D30:L30,"=B") -> 0 | P30: 內滾 | Q30: 6游擊 | R30: G | S30: 中
A31: III | B31: 2 | C31: 蔡奇霖 | D31: CS | E31: SS | F31: F | G31: B | H31: SS | M31: =countif(D31:L31,"=S")+countif(D31:L31,"=SS")+countif(D31:L31,"=CS")+countif(D31:L31,"=IP") -> 3 | N31: =countif(D31:L31,"=F") -> 1 | O31: =countif(D31:L31,"=B") -> 1 | P31: 三振
A32: R | B32: 3 | C32: 梁睿至 | D32: SS | E32: IP | M32: =countif(D32:L32,"=S")+countif(D32:L32,"=SS")+countif(D32:L32,"=CS")+countif(D32:L32,"=IP") -> 2 | N32: =countif(D32:L32,"=F") -> 0 | O32: =countif(D32:L32,"=B") -> 0 | P32: 一安 | Q32: 9右外 | R32: L | S32: 強 | U32: 1 | W32: 1
A33: R | B33: 4 | C33: 許振謙 | D33: B | E33: B | F33: B | G33: B | M33: =countif(D33:L33,"=S")+countif(D33:L33,"=SS")+countif(D33:L33,"=CS")+countif(D33:L33,"=IP") -> 0 | N33: =countif(D33:L33,"=F") -> 0 | O33: =countif(D33:L33,"=B") -> 4 | P33: 保送
A34: I | B34: 5 | C34: 劉哲宏 | D34: B | E34: CS | F34: F | G34: CS | M34: =countif(D34:L34,"=S")+countif(D34:L34,"=SS")+countif(D34:L34,"=CS")+countif(D34:L34,"=IP") -> 2 | N34: =countif(D34:L34,"=F") -> 1 | O34: =countif(D34:L34,"=B") -> 1 | P34: 三振
A35: R | B35: 6 | C35: 劉品辰 | D35: IP | M35: =countif(D35:L35,"=S")+countif(D35:L35,"=SS")+countif(D35:L35,"=CS")+countif(D35:L35,"=IP") -> 1 | N35: =countif(D35:L35,"=F") -> 0 | O35: =countif(D35:L35,"=B") -> 0 | P35: 二安 | Q35: 7左外 | R35: L | S35: 強 | W35: 1 | X35: 1
A36: II | B36: 7 | C36: 王廷宇 | D36: IP | M36: =countif(D36:L36,"=S")+countif(D36:L36,"=SS")+countif(D36:L36,"=CS")+countif(D36:L36,"=IP") -> 1 | N36: =countif(D36:L36,"=F") -> 0 | O36: =countif(D36:L36,"=B") -> 0 | P36: 內飛 | Q36: 6游擊 | R36: L | S36: 中 | W36: 1
A37: R | B37: 8 | C37: 吳藹倫 | D37: B | E37: B | F37: F | G37: B | H37: B | M37: =countif(D37:L37,"=S")+countif(D37:L37,"=SS")+countif(D37:L37,"=CS")+countif(D37:L37,"=IP") -> 0 | N37: =countif(D37:L37,"=F") -> 1 | O37: =countif(D37:L37,"=B") -> 4 | P37: 保送 | W37: 1
B38: 9 | C38: 鄭羣燁 | D38: IP | M38: =countif(D38:L38,"=S")+countif(D38:L38,"=SS")+countif(D38:L38,"=CS")+countif(D38:L38,"=IP") -> 1 | N38: =countif(D38:L38,"=F") -> 0 | O38: =countif(D38:L38,"=B") -> 0 | P38: 三安 | Q38: 7左外 | R38: F | S38: 強 | X38: 3 | Y38: 再見安打
B39: 1 | M39: =countif(D39:L39,"=S")+countif(D39:L39,"=SS")+countif(D39:L39,"=CS")+countif(D39:L39,"=IP") -> 0 | N39: =countif(D39:L39,"=F") -> 0 | O39: =countif(D39:L39,"=B") -> 0
B40: 2 | M40: =countif(D40:L40,"=S")+countif(D40:L40,"=SS")+countif(D40:L40,"=CS")+countif(D40:L40,"=IP") -> 0 | N40: =countif(D40:L40,"=F") -> 0 | O40: =countif(D40:L40,"=B") -> 0
...

Sheet 投球守備
A1: 結果 | B1: 棒次 | C1: 投手姓名 | D1: 逐球 | M1: 好 | N1: 界外 | O1: 壞 | P1: 打擊結果 | Q1: 擊球軌跡 | S1: 內容 | T1: 盜壘 | U1: 失誤進壘 | V1: 壘死 | W1: 得分 | X1: 打點 | Y1: 備註
A2: I | B2: 1 | C2: 范立 | D2: B | E2: F | F2: SS | G2: CS | H2: IP | M2: =countif(D2:L2,"=S")+countif(D2:L2,"=SS")+countif(D2:L2,"=CS")+countif(D2:L2,"=IP") -> 3 | N2: =countif(D2:L2,"=F") -> 1 | O2: =countif(D2:L2,"=B") -> 1 | P2: 內滾 | Q2: 4 | R2: G | S2: 強 | T2: 1 | V2: 0 | W2: 0 | X2: 1
A3: ER | B3: 1 | C3: 林昱丞 | D3: B | E3: IP | M3: =countif(D3:L3,"=S")+countif(D3:L3,"=SS")+countif(D3:L3,"=CS")+countif(D3:L3,"=IP") -> 1 | N3: =countif(D3:L3,"=F") -> 0 | O3: =countif(D3:L3,"=B") -> 1 | P3: 一安 | Q3: 3一壘 | R3: G | S3: 弱 | U3: 1 | W3: 1
A4: L | B4: 2 | C4: 林昱丞 | D4: B | E4: B | F4: F | G4: CS | H4: B | I4: IP | M4: =countif(D4:L4,"=S")+countif(D4:L4,"=SS")+countif(D4:L4,"=CS")+countif(D4:L4,"=IP") -> 2 | N4: =countif(D4:L4,"=F") -> 1 | O4: =countif(D4:L4,"=B") -> 3 | P4: 一安 | Q4: 7左外 | R4: G | S4: 強 | T4: 1 | X4: 1
A5: II | B5: 3 | C5: 林昱丞 | D5: B | E5: CS | F5: IP | M5: =countif(D5:L5,"=S")+countif(D5:L5,"=SS")+countif(D5:L5,"=CS")+countif(D5:L5,"=IP") -> 2 | N5: =countif(D5:L5,"=F") -> 0 | O5: =countif(D5:L5,"=B") -> 1 | P5: 一安 | Q5: 8中外 | R5: L | S5: 強 | V5: 1 | Y5: 外野助殺
A6: I | B6: 4 | C6: 林昱丞 | D6: SS | E6: F | F6: IP | M6: =countif(D6:L6,"=S")+countif(D6:L6,"=SS")+countif(D6:L6,"=CS")+countif(D6:L6,"=IP") -> 2 | N6: =countif(D6:L6,"=F") -> 1 | O6: =countif(D6:L6,"=B") -> 0 | P6: 外飛 | Q6: 9右外 | R6: F | S6: 中
A7: III | B7: 5 | C7: 林昱丞 | D7: F | E7: SS | F7: B | G7: B | H7: B | I7: F | J7: SS | M7: =countif(D7:L7,"=S")+countif(D7:L7,"=SS")+countif(D7:L7,"=CS")+countif(D7:L7,"=IP") -> 2 | N7: =countif(D7:L7,"=F") -> 2 | O7: =countif(D7:L7,"=B") -> 3 | P7: 三振
A8: I | B8: 6 | C8: 林昱丞 | D8: SS | E8: IP | M8: =countif(D8:L8,"=S")+countif(D8:L8,"=SS")+countif(D8:L8,"=CS")+countif(D8:L8,"=IP") -> 2 | N8: =countif(D8:L8,"=F") -> 0 | O8: =countif(D8:L8,"=B") -> 0 | P8: 內滾 | Q8: 5三壘 | R8: G | S8: 弱
A9: II | B9: 7 | C9: 林昱丞 | D9: B | E9: SS | F9: IP | M9: =countif(D9:L9,"=S")+countif(D9:L9,"=SS")+countif(D9:L9,"=CS")+countif(D9:L9,"=IP") -> 2 | N9: =countif(D9:L9,"=F") -> 0 | O9: =countif(D9:L9,"=B") -> 1 | P9: 外飛 | Q9: 4二壘 | R9: L | S9: 中
A10: III | B10: 8 | C10: 林昱丞 | D10: SS | E10: B | F10: F | G10: SS | M10: =countif(D10:L10,"=S")+countif(D10:L10,"=SS")+countif(D10:L10,"=CS")+countif(D10:L10,"=IP") -> 2 | N10: =countif(D10:L10,"=F") -> 1 | O10: =countif(D10:L10,"=B") -> 1 | P10: 三振
A11: I | B11: 9 | C11: 林昱丞 | D11: CS | E11: B | F11: CS | G11: CS | M11: =countif(D11:L11,"=S")+countif(D11:L11,"=SS")+countif(D11:L11,"=CS")+countif(D11:L11,"=IP") -> 3 | N11: =countif(D11:L11,"=F") -> 0 | O11: =countif(D11:L11,"=B") -> 1 | P11: 三振
A12: L | B12: 1 | C12: 林昱丞 | D12: B | E12: B | F12: B | G12: F | H12: SS | I12: F | J12: B | M12: =countif(D12:L12,"=S")+countif(D12:L12,"=SS")+countif(D12:L12,"=CS")+countif(D12:L12,"=IP") -> 1 | N12: =countif(D12:L12,"=F") -> 2 | O12: =countif(D12:L12,"=B") -> 4 | P12: 保送
A13: II | B13: 2 | C13: 林昱丞 | D13: IP | M13: =countif(D13:L13,"=S")+countif(D13:L13,"=SS")+countif(D13:L13,"=CS")+countif(D13:L13,"=IP") -> 1 | N13: =countif(D13:L13,"=F") -> 0 | O13: =countif(D13:L13,"=B") -> 0 | P13: 外飛 | Q13: 7左外 | R13: F | S13: 中
A14: III | B14: 3 | C14: 林昱丞 | D14: CS | E14: B | M14: =countif(D14:L14,"=S")+countif(D14:L14,"=SS")+countif(D14:L14,"=CS")+countif(D14:L14,"=IP") -> 1 | N14: =countif(D14:L14,"=F") -> 0 | O14: =countif(D14:L14,"=B") -> 1 | P14: 外飛 | Q14: 8中外 | R14: F | S14: 中
A15: I | B15: 4 | C15: 林昱丞 | D15: IP | M15: =countif(D15:L15,"=S")+countif(D15:L15,"=SS")+countif(D15:L15,"=CS")+countif(D15:L15,"=IP") -> 1 | N15: =countif(D15:L15,"=F") -> 0 | O15: =countif(D15:L15,"=B") -> 0 | P15: 外飛 | Q15: 7左外 | R15: F | S15: 中
A16: II | B16: 5 | C16: 林昱丞 | D16: F | E16: B | F16: B | G16: CS | M16: =countif(D16:L16,"=S")+countif(D16:L16,"=SS")+countif(D16:L16,"=CS")+countif(D16:L16,"=IP") -> 1 | N16: =countif(D16:L16,"=F") -> 1 | O16: =countif(D16:L16,"=B") -> 2 | P16: 內滾 | Q16: 5三壘 | R16: G | S16: 中
A17: L | B17: 6 | C17: 林昱丞 | D17: B | E17: B | F17: F | G17: IP | M17: =countif(D17:L17,"=S")+countif(D17:L17,"=SS")+countif(D17:L17,"=CS")+countif(D17:L17,"=IP") -> 1 | N17: =countif(D17:L17,"=F") -> 1 | O17: =countif(D17:L17,"=B") -> 2 | P17: 一安 | Q17: 7左外 | R17: F | S17: 中
A18: III | B18: 7 | C18: 林昱丞 | D18: SS | E18: CS | F18: SS | M18: =countif(D18:L18,"=S")+countif(D18:L18,"=SS")+countif(D18:L18,"=CS")+countif(D18:L18,"=IP") -> 3 | N18: =countif(D18:L18,"=F") -> 0 | O18: =countif(D18:L18,"=B") -> 0 | P18: 三振
A19: I | B19: 8 | C19: 林昱丞 | D19: B | E19: B | F19: B | G19: CS | H19: IP | M19: =countif(D19:L19,"=S")+countif(D19:L19,"=SS")+countif(D19:L19,"=CS")+countif(D19:L19,"=IP") -> 2 | N19: =countif(D19:L19,"=F") -> 0 | O19: =countif(D19:L19,"=B") -> 3 | P19: 內滾 | Q19: 1投手 | R19: G | S19: 弱
A20: II | B20: 9 | C20: 林昱丞 | D20: SS | E20: CS | F20: F | G20: B | H20: IP | M20: =countif(D20:L20,"=S")+countif(D20:L20,"=SS")+countif(D20:L20,"=CS")+countif(D20:L20,"=IP") -> 3 | N20: =countif(D20:L20,"=F") -> 1 | O20: =countif(D20:L20,"=B") -> 1 | P20: 內飛 | Q20: 4二壘 | R20: G | S20: 中
A21: ER | B21: 1 | C21: 林昱丞 | D21: B | E21: B | F21: SS | G21: F | H21: B | I21: B | M21: =countif(D21:L21,"=S")+countif(D21:L21,"=SS")+countif(D21:L21,"=CS")+countif(D21:L21,"=IP") -> 1 | N21: =countif(D21:L21,"=F") -> 1 | O21: =countif(D21:L21,"=B") -> 4 | P21: 保送 | T21: 1 | W21: 1
A22: L | B22: 2 | C22: 曾亭維 | D22: B | E22: IP | M22: =countif(D22:L22,"=S")+countif(D22:L22,"=SS")+countif(D22:L22,"=CS")+countif(D22:L22,"=IP") -> 1 | N22: =countif(D22:L22,"=F") -> 0 | O22: =countif(D22:L22,"=B") -> 1 | P22: 二安 | Q22: 5三壘 | R22: G | S22: 強 | U22: 1 | X22: 1
A23: L | B23: 3 | C23: 曾亭維 | D23: B | E23: B | F23: B | G23: B | M23: =countif(D23:L23,"=S")+countif(D23:L23,"=SS")+countif(D23:L23,"=CS")+countif(D23:L23,"=IP") -> 0 | N23: =countif(D23:L23,"=F") -> 0 | O23: =countif(D23:L23,"=B") -> 4 | P23: 保送
A24: III | B24: 4 | C24: 曾亭維 | D24: B | E24: IP | M24: =countif(D24:L24,"=S")+countif(D24:L24,"=SS")+countif(D24:L24,"=CS")+countif(D24:L24,"=IP") -> 1 | N24: =countif(D24:L24,"=F") -> 0 | O24: =countif(D24:L24,"=B") -> 1 | P24: 內滾 | Q24: 6游擊 | R24: G | S24: 中
A25: I | B25: 5 | C25: 曾亭維 | D25: B | E25: F | F25: F | G25: F | H25: B | I25: B | J25: F | K25: CS | M25: =countif(D25:L25,"=S")+countif(D25:L25,"=SS")+countif(D25:L25,"=CS")+countif(D25:L25,"=IP") -> 1 | N25: =countif(D25:L25,"=F") -> 4 | O25: =countif(D25:L25,"=B") -> 3 | P25: 三振
A26: II | B26: 6 | C26: 曾亭維 | D26: B | E26: B | F26: IP | M26: =countif(D26:L26,"=S")+countif(D26:L26,"=SS")+countif(D26:L26,"=CS")+countif(D26:L26,"=IP") -> 1 | N26: =countif(D26:L26,"=F") -> 0 | O26: =countif(D26:L26,"=B") -> 2 | P26: 失誤 | Q26: 5三壘 | R26: G | S26: 中 | V26: 1 | Y26: 牽制出局
A27: R | B27: 7 | C27: 林凱堉 | D27: B | E27: B | F27: CS | G27: CS | H27: IP | M27: =countif(D27:L27,"=S")+countif(D27:L27,"=SS")+countif(D27:L27,"=CS")+countif(D27:L27,"=IP") -> 3 | N27: =countif(D27:L27,"=F") -> 0 | O27: =countif(D27:L27,"=B") -> 2 | P27: 一安 | Q27: 8中外 | R27: L | S27: 中 | U27: 1 | W27: 1
A28: R | B28: 8 | C28: 林凱堉 | D28: B | E28: CS | F28: SS | G28: B | H28: B | I28: B | M28: =countif(D28:L28,"=S")+countif(D28:L28,"=SS")+countif(D28:L28,"=CS")+countif(D28:L28,"=IP") -> 2 | N28: =countif(D28:L28,"=F") -> 0 | O28: =countif(D28:L28,"=B") -> 4 | P28: 保送 | U28: 2 | W28: 1
A29: R | B29: 9 | C29: 林凱堉 | D29: CS | E29: B | F29: B | G29: IP | M29: =countif(D29:L29,"=S")+countif(D29:L29,"=SS")+countif(D29:L29,"=CS")+countif(D29:L29,"=IP") -> 2 | N29: =countif(D29:L29,"=F") -> 0 | O29: =countif(D29:L29,"=B") -> 2 | P29: 一安 | Q29: 7左外 | R29: G | S29: 強 | U29: 2 | W29: 1
A30: R | B30: 1 | C30: 林凱堉 | D30: IP | M30: =countif(D30:L30,"=S")+countif(D30:L30,"=SS")+countif(D30:L30,"=CS")+countif(D30:L30,"=IP") -> 1 | N30: =countif(D30:L30,"=F") -> 0 | O30: =countif(D30:L30,"=B") -> 0 | P30: 失誤 | Q30: 5三壘 | R30: G | S30: 中 | U30: 1 | W30: 1
A31: R | B31: 2 | C31: 林凱堉 | D31: CS | E31: IP | M31: =countif(D31:L31,"=S")+countif(D31:L31,"=SS")+countif(D31:L31,"=CS")+countif(D31:L31,"=IP") -> 2 | N31: =countif(D31:L31,"=F") -> 0 | O31: =countif(D31:L31,"=B") -> 0 | P31: 二安 | Q31: 8中外 | R31: L | S31: 中 | T31: 1 | U31: 1 | W31: 1 | X31: 2
A32: III | B32: 3 | C32: 劉哲宏 | D32: CS | E32: IP | M32: =countif(D32:L32,"=S")+countif(D32:L32,"=SS")+countif(D32:L32,"=CS")+countif(D32:L32,"=IP") -> 2 | N32: =countif(D32:L32,"=F") -> 0 | O32: =countif(D32:L32,"=B") -> 0 | P32: 內飛 | Q32: 4二壘 | R32: L | S32: 中
A33: I | B33: 4 | C33: 劉哲宏 | D33: IP | M33: =countif(D33:L33,"=S")+countif(D33:L33,"=SS")+countif(D33:L33,"=CS")+countif(D33:L33,"=IP") -> 1 | N33: =countif(D33:L33,"=F") -> 0 | O33: =countif(D33:L33,"=B") -> 0 | P33: 一安 | Q33: 9右外 | R33: G | S33: 中 | V33: 1 | Y33: 盜壘刺
A34: L | B34: 5 | C34: 劉哲宏 | D34: B | E34: B | F34: SS | G34: B | H34: F | I34: B | M34: =countif(D34:L34,"=S")+countif(D34:L34,"=SS")+countif(D34:L34,"=CS")+countif(D34:L34,"=IP") -> 1 | N34: =countif(D34:L34,"=F") -> 1 | O34: =countif(D34:L34,"=B") -> 4 | P34: 保送
A35: II | B35: 6 | C35: 劉哲宏 | D35: F | E35: CS | F35: IP | M35: =countif(D35:L35,"=S")+countif(D35:L35,"=SS")+countif(D35:L35,"=CS")+countif(D35:L35,"=IP") -> 2 | N35: =countif(D35:L35,"=F") -> 1 | O35: =countif(D35:L35,"=B") -> 0 | P35: 一安 | Q35: 9右外 | R35: G | S35: 強
A36: III | B36: 7 | C36: 劉哲宏 | D36: B | E36: CS | F36: CS | G36: B | H36: IP | M36: =countif(D36:L36,"=S")+countif(D36:L36,"=SS")+countif(D36:L36,"=CS")+countif(D36:L36,"=IP") -> 3 | N36: =countif(D36:L36,"=F") -> 0 | O36: =countif(D36:L36,"=B") -> 2 | P36: 雙殺 | Q36: 1投手 | R36: G | S36: 中
B37: 8 | M37: =countif(D37:L37,"=S")+countif(D37:L37,"=SS")+countif(D37:L37,"=CS")+countif(D37:L37,"=IP") -> 0 | N37: =countif(D37:L37,"=F") -> 0 | O37: =countif(D37:L37,"=B") -> 0
B38: 9 | M38: =countif(D38:L38,"=S")+countif(D38:L38,"=SS")+countif(D38:L38,"=CS")+countif(D38:L38,"=IP") -> 0 | N38: =countif(D38:L38,"=F") -> 0 | O38: =countif(D38:L38,"=B") -> 0
B39: 1 | M39: =countif(D39:L39,"=S")+countif(D39:L39,"=SS")+countif(D39:L39,"=CS")+countif(D39:L39,"=IP") -> 0 | N39: =countif(D39:L39,"=F") -> 0 | O39: =countif(D39:L39,"=B") -> 0
B40: 2 | M40: =countif(D40:L40,"=S")+countif(D40:L40,"=SS")+countif(D40:L40,"=CS")+countif(D40:L40,"=IP") -> 0 | N40: =countif(D40:L40,"=F") -> 0 | O40: =countif(D40:L40,"=B") -> 0
...

Sheet 名詞解釋
A1: 結果 | B1: I/II/III代表第一、二、三個出局，L代表殘壘，R為得分，投手部分，ER為自責分，R為非自責分
A2: 逐球
A3: SS | B3: 揮棒好球 | C3: CS | D3: 未揮好球 | E3: IP | F3: In Play | G3: B | H3: 壞球 | I3: F | J3: 界外球
A4: 打擊結果
A5: 內滾 | B5: . | C5: 內飛 | D5: 含界外飛球 | E5: 外飛 | F5: 含界外飛球 | G5: 三振 | H5: 含不死三振 | I5: 野選 | J5: 讓壘上跑者出局
A6: 一安 | B6: 含內野一安 | C6: 二安 | D6: . | E6: 三安 | F6: . | G6: 全壘打 | H6: 含場內全壘打
A7: 保送 | B7: 含敬遠 | C7: 觸身 | D7: . | E7: 失誤
A8: 擊球 | B8: 包含位置(1-9)以及滾飛平(G,F,L)
A9: 內容 | B9: 擊球強度為強、中、或弱
A10: 盜壘 | B10: 登記盜壘次數
A11: 失誤進壘 | B11: 登記非經由盜壘推進壘包次數
A12: 壘死 | B12: 登記在壘上出局次數，包含盜壘失敗、進壘時被觸殺等
A13: 得分 | B13: 有得分為1
A14: 打點 | B14: 登記打點數（保送算在內）
A15: 備註 | B15: 需要補充說明的場況
